import pg from "pg";
import config from 'config';
import { logger } from "../logs/logger";
import { NewExcepcion } from "../excepcion/excepcion";

const _host:                    string  = config.get('credenciales.host');
const _user:                    string  = config.get('credenciales.user');
const _password:                string  = config.get('credenciales.password');
const _database:                string  = config.get('credenciales.database');
const _port:                    number  = config.get('credenciales.port');

const conexion = async () => {
        
    const client = new pg.Client({
    
        host    : _host,
        user    : _user,
        password: _password,
        database: _database,
        port    : _port,
        ssl     : false
    });

    await client.connect()
    .then((_res:any) => succes())
    .catch((_error:any) =>  error(_error));
    
    return client;
};

const succes = () => {
    logger.info(`Se hace la conexiÃ³n con exito.`);
}

const error = ( res: void) => {
    throw NewExcepcion('CONEXIONEXCEPCION');
}

export { conexion };